{
 "cells": [
  {
   "cell_type": "code",
   "execution_count": 12,
   "metadata": {},
   "outputs": [],
   "source": [
    "import os"
   ]
  },
  {
   "cell_type": "code",
   "execution_count": 13,
   "metadata": {},
   "outputs": [
    {
     "data": {
      "text/plain": [
       "'c:\\\\Users\\\\Desktop\\\\xReayDetection\\\\research'"
      ]
     },
     "execution_count": 13,
     "metadata": {},
     "output_type": "execute_result"
    }
   ],
   "source": [
    "%pwd"
   ]
  },
  {
   "cell_type": "code",
   "execution_count": 14,
   "metadata": {},
   "outputs": [],
   "source": [
    "os.chdir('../')"
   ]
  },
  {
   "cell_type": "code",
   "execution_count": 15,
   "metadata": {},
   "outputs": [
    {
     "data": {
      "text/plain": [
       "'c:\\\\Users\\\\Desktop\\\\xReayDetection'"
      ]
     },
     "execution_count": 15,
     "metadata": {},
     "output_type": "execute_result"
    }
   ],
   "source": [
    "%pwd"
   ]
  },
  {
   "cell_type": "code",
   "execution_count": 16,
   "metadata": {},
   "outputs": [],
   "source": [
    "\n",
    "from dataclasses import dataclass\n",
    "from pathlib import Path\n",
    "\n",
    "@dataclass(frozen=True)\n",
    "class EvaluationConfig:\n",
    "    path_of_model: Path\n",
    "    training_data: Path\n",
    "    all_params: dict\n",
    "    mlflow_uri: str\n",
    "    params_image_size: list\n",
    "    params_batch_size: int"
   ]
  },
  {
   "cell_type": "code",
   "execution_count": 17,
   "metadata": {},
   "outputs": [],
   "source": [
    "from src.cnnClassifier.constants import *\n",
    "from src.cnnClassifier.utils.common import read_yaml, create_directories, save_json"
   ]
  },
  {
   "cell_type": "code",
   "execution_count": 18,
   "metadata": {},
   "outputs": [],
   "source": [
    "class ConfigurationManager:\n",
    "    def __init__(\n",
    "        self, \n",
    "        config_filepath = CONFIG_FILE_PATH,\n",
    "        params_filepath = PARAMS_FILE_PATH):\n",
    "        self.config = read_yaml(config_filepath)\n",
    "        self.params = read_yaml(params_filepath)\n",
    "        create_directories([self.config.artifacts_root])\n",
    "\n",
    "    \n",
    "    def get_evaluation_config(self) -> EvaluationConfig:\n",
    "        eval_config = EvaluationConfig(\n",
    "            path_of_model=\"artifacts/training/model.h5\",\n",
    "            training_data=\"artifacts/data_ingestion/kidney-ct-scan-image\",\n",
    "            mlflow_uri=\"https://dagshub.com/SRVHCCC/kedney-desease-classification.mlflow\",\n",
    "            all_params=self.params,\n",
    "            params_image_size=self.params.IMAGE_SIZE,\n",
    "            params_batch_size=self.params.BATCH_SIZE\n",
    "        )\n",
    "        return eval_config"
   ]
  },
  {
   "cell_type": "code",
   "execution_count": 19,
   "metadata": {},
   "outputs": [],
   "source": [
    "import tensorflow as tf\n",
    "from pathlib import Path\n",
    "import dagshub\n",
    "import mlflow\n",
    "import mlflow.keras\n",
    "from urllib.parse import urlparse"
   ]
  },
  {
   "cell_type": "code",
   "execution_count": 28,
   "metadata": {},
   "outputs": [],
   "source": [
    "class Evaluation:\n",
    "    def __init__(self, config):\n",
    "        self.config = config\n",
    "\n",
    "    def _valid_generator(self):\n",
    "        datagenerator_kwargs = dict(\n",
    "            rescale=1./255,\n",
    "            validation_split=0.30\n",
    "        )\n",
    "\n",
    "        dataflow_kwargs = dict(\n",
    "            target_size=self.config.params_image_size[:-1],\n",
    "            batch_size=self.config.params_batch_size,\n",
    "            interpolation=\"bilinear\"\n",
    "        )\n",
    "\n",
    "        valid_datagenerator = tf.keras.preprocessing.image.ImageDataGenerator(\n",
    "            **datagenerator_kwargs\n",
    "        )\n",
    "\n",
    "        self.valid_generator = valid_datagenerator.flow_from_directory(\n",
    "            directory=self.config.training_data,\n",
    "            subset=\"validation\",\n",
    "            shuffle=False,\n",
    "            **dataflow_kwargs\n",
    "        )\n",
    "\n",
    "    @staticmethod\n",
    "    def load_model(path: Path) -> tf.keras.Model:\n",
    "        return tf.keras.models.load_model(path)\n",
    "\n",
    "    def evaluation(self):\n",
    "        self.model = self.load_model(self.config.path_of_model)\n",
    "        self._valid_generator()\n",
    "        # Ensure the model and valid_generator are available\n",
    "        if self.model and self.valid_generator:\n",
    "            self.score = self.model.evaluate(self.valid_generator)\n",
    "            self.save_score()\n",
    "        else:\n",
    "            raise ValueError(\"Model or validation generator could not be loaded properly.\")\n",
    "\n",
    "    def save_score(self):\n",
    "        # Ensure score has valid values\n",
    "        if self.score and len(self.score) >= 2:\n",
    "            scores = {\"loss\": self.score[0], \"accuracy\": self.score[1]}\n",
    "            self.save_json(path=Path(\"scores.json\"), data=scores)\n",
    "        else:\n",
    "            raise ValueError(\"Score should have at least loss and accuracy.\")\n",
    "\n",
    "    @staticmethod\n",
    "    def save_json(path: Path, data: dict):\n",
    "        # Saves the data into a JSON file\n",
    "        with open(path, \"w\") as json_file:\n",
    "            json.dump(data, json_file)\n",
    "\n",
    "    def log_into_mlflow(self):\n",
    "        try:\n",
    "            # Set the tracking URI and validate\n",
    "            mlflow.set_registry_uri(self.config.mlflow_uri)\n",
    "            tracking_url_type_store = urlparse(mlflow.get_tracking_uri()).scheme\n",
    "\n",
    "            # Start an MLflow run\n",
    "            with mlflow.start_run():\n",
    "                # Log parameters\n",
    "                if isinstance(self.config.all_params, dict):\n",
    "                    mlflow.log_params(self.config.all_params)\n",
    "                else:\n",
    "                    raise ValueError(\"self.config.all_params must be a dictionary\")\n",
    "\n",
    "                # Log metrics (ensure score has loss and accuracy)\n",
    "                if len(self.score) >= 2:\n",
    "                    mlflow.log_metrics(\n",
    "                        {\"loss\": self.score[0], \"accuracy\": self.score[1]}\n",
    "                    )\n",
    "                else:\n",
    "                    raise ValueError(\"self.score should have at least 2 values: [loss, accuracy]\")\n",
    "\n",
    "                # Log and register the model\n",
    "                if tracking_url_type_store != \"file\":\n",
    "                    mlflow.keras.log_model(self.model, \"model\", registered_model_name=\"VGG16Model\")\n",
    "                else:\n",
    "                    mlflow.keras.log_model(self.model, \"model\")\n",
    "        \n",
    "        except Exception as e:\n",
    "            print(f\"Error logging into MLflow: {e}\")\n",
    "            raise"
   ]
  },
  {
   "cell_type": "code",
   "execution_count": 29,
   "metadata": {},
   "outputs": [
    {
     "name": "stdout",
     "output_type": "stream",
     "text": [
      "Directory created or already exists: artifacts\n",
      "Found 3732 images belonging to 4 classes.\n"
     ]
    },
    {
     "ename": "InvalidArgumentError",
     "evalue": "Graph execution error:\n\nDetected at node 'categorical_crossentropy/softmax_cross_entropy_with_logits' defined at (most recent call last):\n    File \"c:\\Users\\hp\\anaconda3\\envs\\cnncls\\lib\\runpy.py\", line 194, in _run_module_as_main\n      return _run_code(code, main_globals, None,\n    File \"c:\\Users\\hp\\anaconda3\\envs\\cnncls\\lib\\runpy.py\", line 87, in _run_code\n      exec(code, run_globals)\n    File \"c:\\Users\\hp\\anaconda3\\envs\\cnncls\\lib\\site-packages\\ipykernel_launcher.py\", line 18, in <module>\n      app.launch_new_instance()\n    File \"c:\\Users\\hp\\anaconda3\\envs\\cnncls\\lib\\site-packages\\traitlets\\config\\application.py\", line 1075, in launch_instance\n      app.start()\n    File \"c:\\Users\\hp\\anaconda3\\envs\\cnncls\\lib\\site-packages\\ipykernel\\kernelapp.py\", line 739, in start\n      self.io_loop.start()\n    File \"c:\\Users\\hp\\anaconda3\\envs\\cnncls\\lib\\site-packages\\tornado\\platform\\asyncio.py\", line 205, in start\n      self.asyncio_loop.run_forever()\n    File \"c:\\Users\\hp\\anaconda3\\envs\\cnncls\\lib\\asyncio\\base_events.py\", line 570, in run_forever\n      self._run_once()\n    File \"c:\\Users\\hp\\anaconda3\\envs\\cnncls\\lib\\asyncio\\base_events.py\", line 1859, in _run_once\n      handle._run()\n    File \"c:\\Users\\hp\\anaconda3\\envs\\cnncls\\lib\\asyncio\\events.py\", line 81, in _run\n      self._context.run(self._callback, *self._args)\n    File \"c:\\Users\\hp\\anaconda3\\envs\\cnncls\\lib\\site-packages\\ipykernel\\kernelbase.py\", line 545, in dispatch_queue\n      await self.process_one()\n    File \"c:\\Users\\hp\\anaconda3\\envs\\cnncls\\lib\\site-packages\\ipykernel\\kernelbase.py\", line 534, in process_one\n      await dispatch(*args)\n    File \"c:\\Users\\hp\\anaconda3\\envs\\cnncls\\lib\\site-packages\\ipykernel\\kernelbase.py\", line 437, in dispatch_shell\n      await result\n    File \"c:\\Users\\hp\\anaconda3\\envs\\cnncls\\lib\\site-packages\\ipykernel\\ipkernel.py\", line 362, in execute_request\n      await super().execute_request(stream, ident, parent)\n    File \"c:\\Users\\hp\\anaconda3\\envs\\cnncls\\lib\\site-packages\\ipykernel\\kernelbase.py\", line 778, in execute_request\n      reply_content = await reply_content\n    File \"c:\\Users\\hp\\anaconda3\\envs\\cnncls\\lib\\site-packages\\ipykernel\\ipkernel.py\", line 449, in do_execute\n      res = shell.run_cell(\n    File \"c:\\Users\\hp\\anaconda3\\envs\\cnncls\\lib\\site-packages\\ipykernel\\zmqshell.py\", line 549, in run_cell\n      return super().run_cell(*args, **kwargs)\n    File \"c:\\Users\\hp\\anaconda3\\envs\\cnncls\\lib\\site-packages\\IPython\\core\\interactiveshell.py\", line 3009, in run_cell\n      result = self._run_cell(\n    File \"c:\\Users\\hp\\anaconda3\\envs\\cnncls\\lib\\site-packages\\IPython\\core\\interactiveshell.py\", line 3064, in _run_cell\n      result = runner(coro)\n    File \"c:\\Users\\hp\\anaconda3\\envs\\cnncls\\lib\\site-packages\\IPython\\core\\async_helpers.py\", line 129, in _pseudo_sync_runner\n      coro.send(None)\n    File \"c:\\Users\\hp\\anaconda3\\envs\\cnncls\\lib\\site-packages\\IPython\\core\\interactiveshell.py\", line 3269, in run_cell_async\n      has_raised = await self.run_ast_nodes(code_ast.body, cell_name,\n    File \"c:\\Users\\hp\\anaconda3\\envs\\cnncls\\lib\\site-packages\\IPython\\core\\interactiveshell.py\", line 3448, in run_ast_nodes\n      if await self.run_code(code, result, async_=asy):\n    File \"c:\\Users\\hp\\anaconda3\\envs\\cnncls\\lib\\site-packages\\IPython\\core\\interactiveshell.py\", line 3508, in run_code\n      exec(code_obj, self.user_global_ns, self.user_ns)\n    File \"C:\\Users\\hp\\AppData\\Local\\Temp\\ipykernel_12296\\2958471362.py\", line 5, in <module>\n      evaluation.evaluation()\n    File \"C:\\Users\\hp\\AppData\\Local\\Temp\\ipykernel_12296\\2751915994.py\", line 37, in evaluation\n      self.score = self.model.evaluate(self.valid_generator)\n    File \"c:\\Users\\hp\\anaconda3\\envs\\cnncls\\lib\\site-packages\\keras\\src\\utils\\traceback_utils.py\", line 65, in error_handler\n      return fn(*args, **kwargs)\n    File \"c:\\Users\\hp\\anaconda3\\envs\\cnncls\\lib\\site-packages\\keras\\src\\engine\\training.py\", line 2200, in evaluate\n      logs = test_function_runner.run_step(\n    File \"c:\\Users\\hp\\anaconda3\\envs\\cnncls\\lib\\site-packages\\keras\\src\\engine\\training.py\", line 4000, in run_step\n      tmp_logs = self._function(dataset_or_iterator)\n    File \"c:\\Users\\hp\\anaconda3\\envs\\cnncls\\lib\\site-packages\\keras\\src\\engine\\training.py\", line 1972, in test_function\n      return step_function(self, iterator)\n    File \"c:\\Users\\hp\\anaconda3\\envs\\cnncls\\lib\\site-packages\\keras\\src\\engine\\training.py\", line 1956, in step_function\n      outputs = model.distribute_strategy.run(run_step, args=(data,))\n    File \"c:\\Users\\hp\\anaconda3\\envs\\cnncls\\lib\\site-packages\\keras\\src\\engine\\training.py\", line 1944, in run_step\n      outputs = model.test_step(data)\n    File \"c:\\Users\\hp\\anaconda3\\envs\\cnncls\\lib\\site-packages\\keras\\src\\engine\\training.py\", line 1852, in test_step\n      self.compute_loss(x, y, y_pred, sample_weight)\n    File \"c:\\Users\\hp\\anaconda3\\envs\\cnncls\\lib\\site-packages\\keras\\src\\engine\\training.py\", line 1139, in compute_loss\n      return self.compiled_loss(\n    File \"c:\\Users\\hp\\anaconda3\\envs\\cnncls\\lib\\site-packages\\keras\\src\\engine\\compile_utils.py\", line 265, in __call__\n      loss_value = loss_obj(y_t, y_p, sample_weight=sw)\n    File \"c:\\Users\\hp\\anaconda3\\envs\\cnncls\\lib\\site-packages\\keras\\src\\losses.py\", line 142, in __call__\n      losses = call_fn(y_true, y_pred)\n    File \"c:\\Users\\hp\\anaconda3\\envs\\cnncls\\lib\\site-packages\\keras\\src\\losses.py\", line 268, in call\n      return ag_fn(y_true, y_pred, **self._fn_kwargs)\n    File \"c:\\Users\\hp\\anaconda3\\envs\\cnncls\\lib\\site-packages\\keras\\src\\losses.py\", line 2122, in categorical_crossentropy\n      return backend.categorical_crossentropy(\n    File \"c:\\Users\\hp\\anaconda3\\envs\\cnncls\\lib\\site-packages\\keras\\src\\backend.py\", line 5566, in categorical_crossentropy\n      return tf.nn.softmax_cross_entropy_with_logits(\nNode: 'categorical_crossentropy/softmax_cross_entropy_with_logits'\nlogits and labels must be broadcastable: logits_size=[16,2] labels_size=[16,4]\n\t [[{{node categorical_crossentropy/softmax_cross_entropy_with_logits}}]] [Op:__inference_test_function_3401]",
     "output_type": "error",
     "traceback": [
      "\u001b[1;31m---------------------------------------------------------------------------\u001b[0m",
      "\u001b[1;31mInvalidArgumentError\u001b[0m                      Traceback (most recent call last)",
      "Cell \u001b[1;32mIn[29], line 9\u001b[0m\n\u001b[0;32m      6\u001b[0m     evaluation\u001b[38;5;241m.\u001b[39mlog_into_mlflow()\n\u001b[0;32m      8\u001b[0m \u001b[38;5;28;01mexcept\u001b[39;00m \u001b[38;5;167;01mException\u001b[39;00m \u001b[38;5;28;01mas\u001b[39;00m e:\n\u001b[1;32m----> 9\u001b[0m    \u001b[38;5;28;01mraise\u001b[39;00m e\n",
      "Cell \u001b[1;32mIn[29], line 5\u001b[0m\n\u001b[0;32m      3\u001b[0m     eval_config \u001b[38;5;241m=\u001b[39m config\u001b[38;5;241m.\u001b[39mget_evaluation_config()\n\u001b[0;32m      4\u001b[0m     evaluation \u001b[38;5;241m=\u001b[39m Evaluation(eval_config)\n\u001b[1;32m----> 5\u001b[0m     \u001b[43mevaluation\u001b[49m\u001b[38;5;241;43m.\u001b[39;49m\u001b[43mevaluation\u001b[49m\u001b[43m(\u001b[49m\u001b[43m)\u001b[49m\n\u001b[0;32m      6\u001b[0m     evaluation\u001b[38;5;241m.\u001b[39mlog_into_mlflow()\n\u001b[0;32m      8\u001b[0m \u001b[38;5;28;01mexcept\u001b[39;00m \u001b[38;5;167;01mException\u001b[39;00m \u001b[38;5;28;01mas\u001b[39;00m e:\n",
      "Cell \u001b[1;32mIn[28], line 37\u001b[0m, in \u001b[0;36mEvaluation.evaluation\u001b[1;34m(self)\u001b[0m\n\u001b[0;32m     35\u001b[0m \u001b[38;5;66;03m# Ensure the model and valid_generator are available\u001b[39;00m\n\u001b[0;32m     36\u001b[0m \u001b[38;5;28;01mif\u001b[39;00m \u001b[38;5;28mself\u001b[39m\u001b[38;5;241m.\u001b[39mmodel \u001b[38;5;129;01mand\u001b[39;00m \u001b[38;5;28mself\u001b[39m\u001b[38;5;241m.\u001b[39mvalid_generator:\n\u001b[1;32m---> 37\u001b[0m     \u001b[38;5;28mself\u001b[39m\u001b[38;5;241m.\u001b[39mscore \u001b[38;5;241m=\u001b[39m \u001b[38;5;28;43mself\u001b[39;49m\u001b[38;5;241;43m.\u001b[39;49m\u001b[43mmodel\u001b[49m\u001b[38;5;241;43m.\u001b[39;49m\u001b[43mevaluate\u001b[49m\u001b[43m(\u001b[49m\u001b[38;5;28;43mself\u001b[39;49m\u001b[38;5;241;43m.\u001b[39;49m\u001b[43mvalid_generator\u001b[49m\u001b[43m)\u001b[49m\n\u001b[0;32m     38\u001b[0m     \u001b[38;5;28mself\u001b[39m\u001b[38;5;241m.\u001b[39msave_score()\n\u001b[0;32m     39\u001b[0m \u001b[38;5;28;01melse\u001b[39;00m:\n",
      "File \u001b[1;32mc:\\Users\\hp\\anaconda3\\envs\\cnncls\\lib\\site-packages\\keras\\src\\utils\\traceback_utils.py:70\u001b[0m, in \u001b[0;36mfilter_traceback.<locals>.error_handler\u001b[1;34m(*args, **kwargs)\u001b[0m\n\u001b[0;32m     67\u001b[0m     filtered_tb \u001b[38;5;241m=\u001b[39m _process_traceback_frames(e\u001b[38;5;241m.\u001b[39m__traceback__)\n\u001b[0;32m     68\u001b[0m     \u001b[38;5;66;03m# To get the full stack trace, call:\u001b[39;00m\n\u001b[0;32m     69\u001b[0m     \u001b[38;5;66;03m# `tf.debugging.disable_traceback_filtering()`\u001b[39;00m\n\u001b[1;32m---> 70\u001b[0m     \u001b[38;5;28;01mraise\u001b[39;00m e\u001b[38;5;241m.\u001b[39mwith_traceback(filtered_tb) \u001b[38;5;28;01mfrom\u001b[39;00m \u001b[38;5;28;01mNone\u001b[39;00m\n\u001b[0;32m     71\u001b[0m \u001b[38;5;28;01mfinally\u001b[39;00m:\n\u001b[0;32m     72\u001b[0m     \u001b[38;5;28;01mdel\u001b[39;00m filtered_tb\n",
      "File \u001b[1;32mc:\\Users\\hp\\anaconda3\\envs\\cnncls\\lib\\site-packages\\tensorflow\\python\\eager\\execute.py:53\u001b[0m, in \u001b[0;36mquick_execute\u001b[1;34m(op_name, num_outputs, inputs, attrs, ctx, name)\u001b[0m\n\u001b[0;32m     51\u001b[0m \u001b[38;5;28;01mtry\u001b[39;00m:\n\u001b[0;32m     52\u001b[0m   ctx\u001b[38;5;241m.\u001b[39mensure_initialized()\n\u001b[1;32m---> 53\u001b[0m   tensors \u001b[38;5;241m=\u001b[39m pywrap_tfe\u001b[38;5;241m.\u001b[39mTFE_Py_Execute(ctx\u001b[38;5;241m.\u001b[39m_handle, device_name, op_name,\n\u001b[0;32m     54\u001b[0m                                       inputs, attrs, num_outputs)\n\u001b[0;32m     55\u001b[0m \u001b[38;5;28;01mexcept\u001b[39;00m core\u001b[38;5;241m.\u001b[39m_NotOkStatusException \u001b[38;5;28;01mas\u001b[39;00m e:\n\u001b[0;32m     56\u001b[0m   \u001b[38;5;28;01mif\u001b[39;00m name \u001b[38;5;129;01mis\u001b[39;00m \u001b[38;5;129;01mnot\u001b[39;00m \u001b[38;5;28;01mNone\u001b[39;00m:\n",
      "\u001b[1;31mInvalidArgumentError\u001b[0m: Graph execution error:\n\nDetected at node 'categorical_crossentropy/softmax_cross_entropy_with_logits' defined at (most recent call last):\n    File \"c:\\Users\\hp\\anaconda3\\envs\\cnncls\\lib\\runpy.py\", line 194, in _run_module_as_main\n      return _run_code(code, main_globals, None,\n    File \"c:\\Users\\hp\\anaconda3\\envs\\cnncls\\lib\\runpy.py\", line 87, in _run_code\n      exec(code, run_globals)\n    File \"c:\\Users\\hp\\anaconda3\\envs\\cnncls\\lib\\site-packages\\ipykernel_launcher.py\", line 18, in <module>\n      app.launch_new_instance()\n    File \"c:\\Users\\hp\\anaconda3\\envs\\cnncls\\lib\\site-packages\\traitlets\\config\\application.py\", line 1075, in launch_instance\n      app.start()\n    File \"c:\\Users\\hp\\anaconda3\\envs\\cnncls\\lib\\site-packages\\ipykernel\\kernelapp.py\", line 739, in start\n      self.io_loop.start()\n    File \"c:\\Users\\hp\\anaconda3\\envs\\cnncls\\lib\\site-packages\\tornado\\platform\\asyncio.py\", line 205, in start\n      self.asyncio_loop.run_forever()\n    File \"c:\\Users\\hp\\anaconda3\\envs\\cnncls\\lib\\asyncio\\base_events.py\", line 570, in run_forever\n      self._run_once()\n    File \"c:\\Users\\hp\\anaconda3\\envs\\cnncls\\lib\\asyncio\\base_events.py\", line 1859, in _run_once\n      handle._run()\n    File \"c:\\Users\\hp\\anaconda3\\envs\\cnncls\\lib\\asyncio\\events.py\", line 81, in _run\n      self._context.run(self._callback, *self._args)\n    File \"c:\\Users\\hp\\anaconda3\\envs\\cnncls\\lib\\site-packages\\ipykernel\\kernelbase.py\", line 545, in dispatch_queue\n      await self.process_one()\n    File \"c:\\Users\\hp\\anaconda3\\envs\\cnncls\\lib\\site-packages\\ipykernel\\kernelbase.py\", line 534, in process_one\n      await dispatch(*args)\n    File \"c:\\Users\\hp\\anaconda3\\envs\\cnncls\\lib\\site-packages\\ipykernel\\kernelbase.py\", line 437, in dispatch_shell\n      await result\n    File \"c:\\Users\\hp\\anaconda3\\envs\\cnncls\\lib\\site-packages\\ipykernel\\ipkernel.py\", line 362, in execute_request\n      await super().execute_request(stream, ident, parent)\n    File \"c:\\Users\\hp\\anaconda3\\envs\\cnncls\\lib\\site-packages\\ipykernel\\kernelbase.py\", line 778, in execute_request\n      reply_content = await reply_content\n    File \"c:\\Users\\hp\\anaconda3\\envs\\cnncls\\lib\\site-packages\\ipykernel\\ipkernel.py\", line 449, in do_execute\n      res = shell.run_cell(\n    File \"c:\\Users\\hp\\anaconda3\\envs\\cnncls\\lib\\site-packages\\ipykernel\\zmqshell.py\", line 549, in run_cell\n      return super().run_cell(*args, **kwargs)\n    File \"c:\\Users\\hp\\anaconda3\\envs\\cnncls\\lib\\site-packages\\IPython\\core\\interactiveshell.py\", line 3009, in run_cell\n      result = self._run_cell(\n    File \"c:\\Users\\hp\\anaconda3\\envs\\cnncls\\lib\\site-packages\\IPython\\core\\interactiveshell.py\", line 3064, in _run_cell\n      result = runner(coro)\n    File \"c:\\Users\\hp\\anaconda3\\envs\\cnncls\\lib\\site-packages\\IPython\\core\\async_helpers.py\", line 129, in _pseudo_sync_runner\n      coro.send(None)\n    File \"c:\\Users\\hp\\anaconda3\\envs\\cnncls\\lib\\site-packages\\IPython\\core\\interactiveshell.py\", line 3269, in run_cell_async\n      has_raised = await self.run_ast_nodes(code_ast.body, cell_name,\n    File \"c:\\Users\\hp\\anaconda3\\envs\\cnncls\\lib\\site-packages\\IPython\\core\\interactiveshell.py\", line 3448, in run_ast_nodes\n      if await self.run_code(code, result, async_=asy):\n    File \"c:\\Users\\hp\\anaconda3\\envs\\cnncls\\lib\\site-packages\\IPython\\core\\interactiveshell.py\", line 3508, in run_code\n      exec(code_obj, self.user_global_ns, self.user_ns)\n    File \"C:\\Users\\hp\\AppData\\Local\\Temp\\ipykernel_12296\\2958471362.py\", line 5, in <module>\n      evaluation.evaluation()\n    File \"C:\\Users\\hp\\AppData\\Local\\Temp\\ipykernel_12296\\2751915994.py\", line 37, in evaluation\n      self.score = self.model.evaluate(self.valid_generator)\n    File \"c:\\Users\\hp\\anaconda3\\envs\\cnncls\\lib\\site-packages\\keras\\src\\utils\\traceback_utils.py\", line 65, in error_handler\n      return fn(*args, **kwargs)\n    File \"c:\\Users\\hp\\anaconda3\\envs\\cnncls\\lib\\site-packages\\keras\\src\\engine\\training.py\", line 2200, in evaluate\n      logs = test_function_runner.run_step(\n    File \"c:\\Users\\hp\\anaconda3\\envs\\cnncls\\lib\\site-packages\\keras\\src\\engine\\training.py\", line 4000, in run_step\n      tmp_logs = self._function(dataset_or_iterator)\n    File \"c:\\Users\\hp\\anaconda3\\envs\\cnncls\\lib\\site-packages\\keras\\src\\engine\\training.py\", line 1972, in test_function\n      return step_function(self, iterator)\n    File \"c:\\Users\\hp\\anaconda3\\envs\\cnncls\\lib\\site-packages\\keras\\src\\engine\\training.py\", line 1956, in step_function\n      outputs = model.distribute_strategy.run(run_step, args=(data,))\n    File \"c:\\Users\\hp\\anaconda3\\envs\\cnncls\\lib\\site-packages\\keras\\src\\engine\\training.py\", line 1944, in run_step\n      outputs = model.test_step(data)\n    File \"c:\\Users\\hp\\anaconda3\\envs\\cnncls\\lib\\site-packages\\keras\\src\\engine\\training.py\", line 1852, in test_step\n      self.compute_loss(x, y, y_pred, sample_weight)\n    File \"c:\\Users\\hp\\anaconda3\\envs\\cnncls\\lib\\site-packages\\keras\\src\\engine\\training.py\", line 1139, in compute_loss\n      return self.compiled_loss(\n    File \"c:\\Users\\hp\\anaconda3\\envs\\cnncls\\lib\\site-packages\\keras\\src\\engine\\compile_utils.py\", line 265, in __call__\n      loss_value = loss_obj(y_t, y_p, sample_weight=sw)\n    File \"c:\\Users\\hp\\anaconda3\\envs\\cnncls\\lib\\site-packages\\keras\\src\\losses.py\", line 142, in __call__\n      losses = call_fn(y_true, y_pred)\n    File \"c:\\Users\\hp\\anaconda3\\envs\\cnncls\\lib\\site-packages\\keras\\src\\losses.py\", line 268, in call\n      return ag_fn(y_true, y_pred, **self._fn_kwargs)\n    File \"c:\\Users\\hp\\anaconda3\\envs\\cnncls\\lib\\site-packages\\keras\\src\\losses.py\", line 2122, in categorical_crossentropy\n      return backend.categorical_crossentropy(\n    File \"c:\\Users\\hp\\anaconda3\\envs\\cnncls\\lib\\site-packages\\keras\\src\\backend.py\", line 5566, in categorical_crossentropy\n      return tf.nn.softmax_cross_entropy_with_logits(\nNode: 'categorical_crossentropy/softmax_cross_entropy_with_logits'\nlogits and labels must be broadcastable: logits_size=[16,2] labels_size=[16,4]\n\t [[{{node categorical_crossentropy/softmax_cross_entropy_with_logits}}]] [Op:__inference_test_function_3401]"
     ]
    }
   ],
   "source": [
    "try:\n",
    "    config = ConfigurationManager()\n",
    "    eval_config = config.get_evaluation_config()\n",
    "    evaluation = Evaluation(eval_config)\n",
    "    evaluation.evaluation()\n",
    "    evaluation.log_into_mlflow()\n",
    "\n",
    "except Exception as e:\n",
    "   raise e"
   ]
  },
  {
   "cell_type": "code",
   "execution_count": null,
   "metadata": {},
   "outputs": [],
   "source": []
  }
 ],
 "metadata": {
  "kernelspec": {
   "display_name": "cnncls",
   "language": "python",
   "name": "python3"
  },
  "language_info": {
   "codemirror_mode": {
    "name": "ipython",
    "version": 3
   },
   "file_extension": ".py",
   "mimetype": "text/x-python",
   "name": "python",
   "nbconvert_exporter": "python",
   "pygments_lexer": "ipython3",
   "version": "3.8.19"
  }
 },
 "nbformat": 4,
 "nbformat_minor": 2
}
